-----
Traceback:
Traceback (most recent call last):
  File "/home/vulder/git/vara-tool-suite/varats/utils/experiment_util.py", line 42, in __call__
    return self.__func(*args, **kwargs)
  File "/home/vulder/.local/lib/python3.7/site-packages/benchbuild/utils/run.py", line 361, in wrap_in_builddir_func
    return func(self, *args, **kwargs)
  File "/home/vulder/.local/lib/python3.7/site-packages/benchbuild/utils/run.py", line 376, in wrap_store_config
    return func(self, *args, **kwargs)
  File "/home/vulder/git/vara-tool-suite/varats/projects/c_projects/xz.py", line 77, in compile
    run(make["-j", int(BB_CFG["jobs"])])
  File "/home/vulder/.local/lib/python3.7/site-packages/benchbuild/utils/run.py", line 315, in run
    return command & TEE(retcode=retcode)
  File "/home/vulder/.local/lib/python3.7/site-packages/plumbum/commands/modifiers.py", line 236, in __rand__
    return p.returncode, stdout, stderr
  File "/usr/lib/python3.7/contextlib.py", line 119, in __exit__
    next(self.gen)
  File "/home/vulder/.local/lib/python3.7/site-packages/plumbum/commands/base.py", line 205, in bgrun
    runner()
  File "/home/vulder/.local/lib/python3.7/site-packages/plumbum/commands/base.py", line 194, in runner
    return run_proc(p, retcode, timeout)
  File "/home/vulder/.local/lib/python3.7/site-packages/plumbum/commands/processes.py", line 247, in run_proc
    return _check_process(proc, retcode, timeout, stdout, stderr)
  File "/home/vulder/.local/lib/python3.7/site-packages/plumbum/commands/processes.py", line 23, in _check_process
    proc.verify(retcode, timeout, stdout, stderr)
  File "/home/vulder/.local/lib/python3.7/site-packages/plumbum/machines/base.py", line 26, in verify
    stderr)
plumbum.commands.processes.ProcessExecutionError: Unexpected exit code: 2
Command line: | /usr/bin/make -j 4
